W0330 01:49:31.388000 1795 torch/distributed/run.py:792] 
W0330 01:49:31.388000 1795 torch/distributed/run.py:792] *****************************************
W0330 01:49:31.388000 1795 torch/distributed/run.py:792] Setting OMP_NUM_THREADS environment variable for each process to be 1 in default, to avoid your system being overloaded, please further tune the variable for optimal performance in your application as needed. 
W0330 01:49:31.388000 1795 torch/distributed/run.py:792] *****************************************
[INFO] Using device: cuda
[INFO] Resolved dataset path: /workspace/GAN-Models/model/data/mnist/
Traceback (most recent call last):
  File "/workspace/GAN-Models/model/GAN/full_script.py", line 129, in <module>
    train_data = load_mnist_full()
  File "/workspace/GAN-Models/model/GAN/full_script.py", line 30, in load_mnist_full
    raise FileNotFoundError(f"The resolved path '{data_path}' does not exist.")
FileNotFoundError: The resolved path '/workspace/GAN-Models/model/data/mnist/' does not exist.
[INFO] Using device: cuda
[INFO] Resolved dataset path: /workspace/GAN-Models/model/data/mnist/
Traceback (most recent call last):
  File "/workspace/GAN-Models/model/GAN/full_script.py", line 129, in <module>
    train_data = load_mnist_full()
  File "/workspace/GAN-Models/model/GAN/full_script.py", line 30, in load_mnist_full
    raise FileNotFoundError(f"The resolved path '{data_path}' does not exist.")
FileNotFoundError: The resolved path '/workspace/GAN-Models/model/data/mnist/' does not exist.
W0330 01:49:34.216000 1795 torch/distributed/elastic/multiprocessing/api.py:897] Sending process 1860 closing signal SIGTERM
E0330 01:49:34.283000 1795 torch/distributed/elastic/multiprocessing/api.py:869] failed (exitcode: 1) local_rank: 1 (pid: 1861) of binary: /venv/main/bin/python3.10
Traceback (most recent call last):
  File "/venv/main/bin/torchrun", line 8, in <module>
    sys.exit(main())
  File "/venv/main/lib/python3.10/site-packages/torch/distributed/elastic/multiprocessing/errors/__init__.py", line 355, in wrapper
    return f(*args, **kwargs)
  File "/venv/main/lib/python3.10/site-packages/torch/distributed/run.py", line 918, in main
    run(args)
  File "/venv/main/lib/python3.10/site-packages/torch/distributed/run.py", line 909, in run
    elastic_launch(
  File "/venv/main/lib/python3.10/site-packages/torch/distributed/launcher/api.py", line 138, in __call__
    return launch_agent(self._config, self._entrypoint, list(args))
  File "/venv/main/lib/python3.10/site-packages/torch/distributed/launcher/api.py", line 269, in launch_agent
    raise ChildFailedError(
torch.distributed.elastic.multiprocessing.errors.ChildFailedError: 
============================================================
full_script.py FAILED
------------------------------------------------------------
Failures:
  <NO_OTHER_FAILURES>
------------------------------------------------------------
Root Cause (first observed failure):
[0]:
  time      : 2025-03-30_01:49:34
  host      : 108acb44de28
  rank      : 1 (local_rank: 1)
  exitcode  : 1 (pid: 1861)
  error_file: <N/A>
  traceback : To enable traceback see: https://pytorch.org/docs/stable/elastic/errors.html
============================================================
